<?xml version="1.0"?>
<robot name="Maximus_urdf">
  <link name="base_link">
    <visual>
      <geometry>
        <box size="0.1 .28 .005"/>
      </geometry>
    </visual>
  </link>

  <link name="between_wheels">
    <visual>
      <geometry>
        <box size="0.085 .16 .005"/>
      </geometry>
    </visual>
  </link>

  <joint name="base_to_bet_wheels" type="fixed">
    <parent link="base_link"/>
    <child link="between_wheels"/>
    <origin xyz="-0.0925 0 0"/>
  </joint>

  <link name="right_wheel">
    <visual>
      <geometry>
        <cylinder length="0.005" radius="0.07"/>
      </geometry>
      <origin rpy="1.57075 0 0" xyz="0 0 -0.035"/>
    </visual>
  </link>

  <joint name="base_to_right_wheel" type="fixed">
    <parent link="between_wheels"/>
    <child link="right_wheel"/>
    <origin xyz="0 0.0975 0"/>
  </joint>

  <link name="left_wheel">
    <visual>
      <geometry>
        <cylinder length="0.005" radius="0.07"/>
      </geometry>
      <origin rpy="1.57075 0 0" xyz="0 0 -0.035"/>
    </visual>
  </link>

  <joint name="base_to_left_wheel" type="fixed">
    <parent link="between_wheels"/>
    <child link="left_wheel"/>
    <origin xyz="0 -0.0975 0"/>
  </joint>



  <link name="elevator">
    <visual>
      <geometry>
        <box size="0.085 .16 .005"/>
      </geometry>
    </visual>
  </link>

  <joint name="elevator_joint" type="prismatic">
    <parent link="base_link"/>
    <child link="elevator"/>
    <axis xyz="0 0 1"/>
    <limit effort="1000.0" lower="0" upper="0.38" velocity="100"/>
    <origin rpy="0 0 0" xyz="0.05 0 0.005"/>
  </joint>


</robot>

